Workbook

Sheet WACC
A1: Apple Inc. (AAPL) - Cost of Capital (WACC)
A2: CAPM & Capital Structure Analysis | Date: 2026-08-19
A4: 1. COST OF EQUITY (CAPM)
A5: Risk-Free Rate (10Y US Treasury) | B5: 0.0469
A6: Beta (5-Year Monthly vs S&P 500) | B6: 1.09
A7: Equity Risk Premium (ERP) | B7: 0.055
A8: Cost of Equity (Ke) | B8: =B5+B6*B7
A9: 2. COST OF DEBT
A10: Credit Rating (S&P / Moody's) | B10: AA+
A11: Pre-Tax Cost of Debt (Kd) | B11: 0.048
A12: Marginal / Effective Tax Rate | B12: =DCF!$C$12
A13: After-Tax Cost of Debt (Kd * (1 - t)) | B13: =B11*(1-B12)
A15: 3. CAPITAL STRUCTURE & MARKET VALUES
A16: Current Stock Price ($) | B16: =DCF!$C$8
A17: Diluted Shares Outstanding (M) | B17: =DCF!$C$9
A18: Market Capitalization ($M) | B18: =B16*B17
A19: Total Debt ($M) | B19: =DCF!$C$11
A20: Cash & Marketable Securities ($M) | B20: =DCF!$C$10
A21: Net Debt / (Net Cash) ($M) | B21: =B19-B20
A22: Enterprise Value ($M) | B22: =B18+B21
A24: 4. WEIGHTED AVERAGE COST OF CAPITAL (WACC)
A25: Component | B25: Weight | C25: Cost | D25: Contribution
A26: Equity | B26: =B18/B22 | C26: =B8 | D26: =B26*C26
A27: Debt (Net Debt Weight) | B27: =B21/B22 | C27: =B13 | D27: =B27*C27
A28: Market Value Weight / CAPM WACC | B28: =SUM(B26:B27) | C28: - | D28: =D26+D27
A29: Institutional Base WACC (Reflecting Long-Term Tech Target Structure) | B29: 0.078

Sheet DCF
A1: Apple Inc. (AAPL) - 5-Year DCF Valuation Model
A2: Ticker: AAPL | Currency: USD in Millions (except per share) | Date: 2026-08-19
A4: Active Scenario Selector (1 = Bear Case, 2 = Base Case, 3 = Bull Case): | B4: 2
A5: Active Scenario Selected: | B5: =IF(B4=1,"BEAR CASE",IF(B4=2,"BASE CASE","BULL CASE"))
A7: MARKET DATA & CAPITAL STRUCTURE
A8: Current Stock Price ($) | C8: 305.59
A9: Diluted Shares Outstanding (M) | C9: 14590
A10: Cash & Marketable Securities ($M) | C10: 156650
A11: Total Debt ($M) | C11: 106042
A12: Effective Tax Rate (%) | C12: 0.16
A13: Market Capitalization ($M) | C13: =C8*C9
A14: Net Debt / (Net Cash) ($M) | C14: =C11-C10
A15: Enterprise Value ($M) | C15: =C13+C14
A17: SCENARIO 1: BEAR CASE ASSUMPTIONS
A18: Historical / Projection Metric | B18: FY2022A | C18: FY2023A | D18: FY2024A | E18: FY2025A | F18: FY2026E | G18: FY2027E | H18: FY2028E | I18: FY2029E | J18: FY2030E | K18: Terminal
A19: Revenue Growth (%) | F19: 0.04 | G19: 0.035 | H19: 0.03 | I19: 0.025 | J19: 0.02 | K19: 0.02
A20: EBIT Margin (%) | F20: 0.3 | G20: 0.298 | H20: 0.295 | I20: 0.292 | J20: 0.29 | K20: 0.29
A21: D&A (% of Revenue) | F21: 0.029 | G21: 0.029 | H21: 0.029 | I21: 0.029 | J21: 0.029 | K21: 0.029
A22: CapEx (% of Revenue) | F22: 0.027 | G22: 0.027 | H22: 0.027 | I22: 0.027 | J22: 0.027 | K22: 0.027
A23: NWC Change (% of ΔRev) | F23: 0.02 | G23: 0.02 | H23: 0.02 | I23: 0.02 | J23: 0.02 | K23: 0.02
A24: Discount Rate (WACC) | F24: 0.085 | G24: 0.085 | H24: 0.085 | I24: 0.085 | J24: 0.085 | K24: 0.085
A25: Terminal Growth Rate (g) | K25: 0.02
A27: SCENARIO 2: BASE CASE ASSUMPTIONS (CONSENSUS & SERVICES EXPANSION)
A28: Historical / Projection Metric | B28: FY2022A | C28: FY2023A | D28: FY2024A | E28: FY2025A | F28: FY2026E | G28: FY2027E | H28: FY2028E | I28: FY2029E | J28: FY2030E | K28: Terminal
A29: Revenue Growth (%) | F29: 0.07 | G29: 0.065 | H29: 0.055 | I29: 0.045 | J29: 0.035 | K29: 0.025
A30: EBIT Margin (%) | F30: 0.32 | G30: 0.325 | H30: 0.328 | I30: 0.33 | J30: 0.332 | K30: 0.332
A31: D&A (% of Revenue) | F31: 0.028 | G31: 0.028 | H31: 0.028 | I31: 0.028 | J31: 0.028 | K31: 0.028
A32: CapEx (% of Revenue) | F32: 0.025 | G32: 0.025 | H32: 0.025 | I32: 0.025 | J32: 0.025 | K32: 0.025
A33: NWC Change (% of ΔRev) | F33: -0.015 | G33: -0.015 | H33: -0.015 | I33: -0.015 | J33: -0.015 | K33: -0.015
A34: Discount Rate (WACC) | F34: 0.078 | G34: 0.078 | H34: 0.078 | I34: 0.078 | J34: 0.078 | K34: 0.078
A35: Terminal Growth Rate (g) | K35: 0.025
A37: SCENARIO 3: BULL CASE ASSUMPTIONS (AI SUPERCYCLE)
A38: Historical / Projection Metric | B38: FY2022A | C38: FY2023A | D38: FY2024A | E38: FY2025A | F38: FY2026E | G38: FY2027E | H38: FY2028E | I38: FY2029E | J38: FY2030E | K38: Terminal
A39: Revenue Growth (%) | F39: 0.1 | G39: 0.09 | H39: 0.08 | I39: 0.065 | J39: 0.05 | K39: 0.03
A40: EBIT Margin (%) | F40: 0.335 | G40: 0.34 | H40: 0.345 | I40: 0.348 | J40: 0.35 | K40: 0.35
A41: D&A (% of Revenue) | F41: 0.027 | G41: 0.027 | H41: 0.027 | I41: 0.027 | J41: 0.027 | K41: 0.027
A42: CapEx (% of Revenue) | F42: 0.024 | G42: 0.024 | H42: 0.024 | I42: 0.024 | J42: 0.024 | K42: 0.024
A43: NWC Change (% of ΔRev) | F43: -0.02 | G43: -0.02 | H43: -0.02 | I43: -0.02 | J43: -0.02 | K43: -0.02
A44: Discount Rate (WACC) | F44: 0.072 | G44: 0.072 | H44: 0.072 | I44: 0.072 | J44: 0.072 | K44: 0.072
A45: Terminal Growth Rate (g) | K45: 0.03
...
