Workbook

Sheet DCF
A1: Amazon.com, Inc. (NASDAQ: AMZN) - Discounted Cash Flow Valuation Model
A2: Valuation Date: August 19, 2026 | Currency: USD in Millions (except per-share data) | Fiscal Year End: Dec 31
A4: SCENARIO SELECTOR: | B4: 2 | C4: =IF(B4=1,"[ BEAR CASE ACTIVE ]",IF(B4=2,"[ BASE CASE ACTIVE ]","[ BULL CASE ACTIVE ]"))
A6: 1. MARKET DATA & CAPITAL STRUCTURE INPUTS
A8: Current Share Price ($) | B8: 265
A9: Diluted Shares Outstanding (M) | B9: 10740
A10: Market Capitalization ($M) | B10: =B8*B9
A11: Cash, Cash Eq. & Marketable Securities ($M) | B11: 123029
A12: Total Debt ($M) | B12: 65648
A13: Net Debt / (Net Cash) ($M) | B13: =B12-B11
A14: Current Enterprise Value ($M) | B14: =B10+B13
A16: 2. SCENARIO ASSUMPTIONS (BEAR / BASE / BULL)
A18: BEAR CASE ASSUMPTIONS (Scenario 1) | F18: FY2026E | G18: FY2027E | H18: FY2028E | I18: FY2029E | J18: FY2030E
A19: Revenue Growth (%) | F19: 0.1 | G19: 0.09 | H19: 0.08 | I19: 0.07 | J19: 0.06
A20: EBIT Margin (%) | F20: 0.11 | G20: 0.115 | H20: 0.12 | I20: 0.12 | J20: 0.12
A21: D&A (% of Revenue) | F21: 0.09 | G21: 0.088 | H21: 0.085 | I21: 0.083 | J21: 0.08
A22: CapEx (% of Revenue) | F22: 0.155 | G22: 0.145 | H22: 0.135 | I22: 0.125 | J22: 0.115
A23: Change in NWC (% of ΔRev) | F23: -0.01 | G23: -0.01 | H23: -0.01 | I23: -0.01 | J23: -0.01
A24: Tax Rate (%) | F24: 0.21 | G24: 0.21 | H24: 0.21 | I24: 0.21 | J24: 0.21
A25: Terminal Growth Rate (g) | F25: 0.025 | G25: 0.025 | H25: 0.025 | I25: 0.025 | J25: 0.025
A26: Discount Rate (WACC) | F26: 0.095 | G26: 0.095 | H26: 0.095 | I26: 0.095 | J26: 0.095
A28: BASE CASE ASSUMPTIONS (Scenario 2 - Consensus / Recommended) | F28: FY2026E | G28: FY2027E | H28: FY2028E | I28: FY2029E | J28: FY2030E
A29: Revenue Growth (%) | F29: 0.13 | G29: 0.12 | H29: 0.11 | I29: 0.095 | J29: 0.085
A30: EBIT Margin (%) | F30: 0.12 | G30: 0.135 | H30: 0.145 | I30: 0.155 | J30: 0.16
A31: D&A (% of Revenue) | F31: 0.09 | G31: 0.088 | H31: 0.085 | I31: 0.082 | J31: 0.08
A32: CapEx (% of Revenue) | F32: 0.145 | G32: 0.13 | H32: 0.115 | I32: 0.1 | J32: 0.09
A33: Change in NWC (% of ΔRev) | F33: -0.01 | G33: -0.01 | H33: -0.01 | I33: -0.01 | J33: -0.01
A34: Tax Rate (%) | F34: 0.21 | G34: 0.21 | H34: 0.21 | I34: 0.21 | J34: 0.21
A35: Terminal Growth Rate (g) | F35: 0.03 | G35: 0.03 | H35: 0.03 | I35: 0.03 | J35: 0.03
A36: Discount Rate (WACC) | F36: 0.085 | G36: 0.085 | H36: 0.085 | I36: 0.085 | J36: 0.085
A38: BULL CASE ASSUMPTIONS (Scenario 3) | F38: FY2026E | G38: FY2027E | H38: FY2028E | I38: FY2029E | J38: FY2030E
A39: Revenue Growth (%) | F39: 0.155 | G39: 0.145 | H39: 0.13 | I39: 0.115 | J39: 0.1
A40: EBIT Margin (%) | F40: 0.13 | G40: 0.15 | H40: 0.165 | I40: 0.175 | J40: 0.18
A41: D&A (% of Revenue) | F41: 0.09 | G41: 0.085 | H41: 0.08 | I41: 0.078 | J41: 0.075
A42: CapEx (% of Revenue) | F42: 0.135 | G42: 0.12 | H42: 0.105 | I42: 0.09 | J42: 0.08
A43: Change in NWC (% of ΔRev) | F43: -0.01 | G43: -0.01 | H43: -0.01 | I43: -0.01 | J43: -0.01
A44: Tax Rate (%) | F44: 0.21 | G44: 0.21 | H44: 0.21 | I44: 0.21 | J44: 0.21
A45: Terminal Growth Rate (g) | F45: 0.035 | G45: 0.035 | H45: 0.035 | I45: 0.035 | J45: 0.035
A46: Discount Rate (WACC) | F46: 0.078 | G46: 0.078 | H46: 0.078 | I46: 0.078 | J46: 0.078
A48: ACTIVE CONSOLIDATED ASSUMPTIONS (Driven by Case Selector B4) | F48: FY2026E | G48: FY2027E | H48: FY2028E | I48: FY2029E | J48: FY2030E
...

Sheet WACC
A1: Amazon.com, Inc. (AMZN) - Weighted Average Cost of Capital (WACC) Schedule
A2: Valuation Date: August 19, 2026 | Source: Market Data & Capital Asset Pricing Model (CAPM)
A4: 1. COST OF EQUITY CALCULATION (CAPM)
A5: Risk-Free Rate (10-Year US Treasury Yield) | B5: 0.047
A6: Beta (5-Year Monthly vs. S&P 500) | B6: 1.45
A7: Equity Risk Premium (ERP) | B7: 0.055
A8: Cost of Equity (Ke = Rf + Beta * ERP) | B8: =B5+B6*B7
A10: 2. COST OF DEBT CALCULATION
A11: Corporate Credit Rating (S&P / Moody's) | B11: AA / A1
A12: Pre-Tax Cost of Debt (Kd) | B12: 0.05
A13: Effective Corporate Tax Rate (t) | B13: =DCF!$F$54
A14: After-Tax Cost of Debt [Kd * (1 - t)] | B14: =B12*(1-B13)
A16: 3. CAPITAL STRUCTURE & MARKET WEIGHTS
A17: Current Share Price ($) | B17: =DCF!$B$8
A18: Diluted Shares Outstanding (M) | B18: =DCF!$B$9
A19: Market Value of Equity (E) ($M) | B19: =B17*B18
A20: Total Debt ($M) | B20: =DCF!$B$12
A21: Less: Cash & Marketable Securities ($M) | B21: =DCF!$B$11
A22: Net Debt ($M) | B22: =B20-B21
A23: Total Capital Base (E + Debt) ($M) | B23: =B19+B20
A24: Weight of Equity (We = E / Total Capital) | B24: =B19/B23
A25: Weight of Debt (Wd = Debt / Total Capital) | B25: =B20/B23
A27: 4. WEIGHTED AVERAGE COST OF CAPITAL (WACC) SUMMARY
A28: Component | B28: Weight | C28: Cost | D28: Weighted Contribution
A29: Equity (CAPM) | B29: =B24 | C29: =B8 | D29: =B29*C29
A30: Debt (After-Tax) | B30: =B25 | C30: =B14 | D30: =B30*C30
A31: CALCULATED CAPM WACC | D31: =SUM(D29:D30)
A33: BASE CASE TARGET DCF DISCOUNT RATE (WACC) | D33: 0.085
