Workbook

Sheet DCF Valuation
A1: Alphabet Inc. (NASDAQ: GOOGL / GOOG)
A2: Institutional DCF Valuation Model | Report Date: August 19, 2026 | Financial Source: SEC Form 10-K, 10-Q & Consensus Estimates
A4: Active Scenario Selector: | B4: 2 | C4: =IF(B4=1,"[1] BEAR CASE (Antitrust Headwinds / Search Disruption / AI ROI Drag)",IF(B4=2,"[2] BASE CASE (Cloud Scaling / Gemini AI Monetization / Sustained Search Moat)","[3] BULL CASE (Waymo Commercialization / Cloud Hypergrowth / Agentic AI Leadership)"))
A6: I. MARKET DATA & CAPITAL STRUCTURE INPUTS
A7: Current Stock Price ($) | B7: 341.37
A8: Diluted Shares Outstanding (M) | B8: 12200
A9: Implied Equity Market Capitalization ($M) | B9: =B7*B8
A10: Cash, Cash Eq. & Marketable Securities ($M) | B10: 242500
A11: Total Debt (Current + Noncurrent Debt) ($M) | B11: 98200
A12: Net Debt ($M) [Net Cash if negative] | B12: =B11-B10
A13: Implied Enterprise Value ($M) | B13: =B9+B12
A14: Effective Corporate Tax Rate (%) | B14: 0.175
A15: Market Equity Risk Premium (ERP) (%) | B15: 0.055
A16: Long-Term Risk-Free Rate (%) | B16: 0.0469
A17: Equity Beta (5-Year Monthly vs S&P 500) | B17: 1.24
A19: II. SCENARIO DRIVER ASSUMPTIONS (BEAR / BASE / BULL)
A20: SCENARIO 1: BEAR CASE ASSUMPTIONS
A21: Assumption Driver | B21: FY26E | C21: FY27E | D21: FY28E | E21: FY29E | F21: FY30E | G21: Terminal | H21: Parameter Description / Methodology
A22: Revenue Growth Rate (%) | B22: 0.11 | C22: 0.09 | D22: 0.075 | E22: 0.06 | F22: 0.05 | G22: 0.025 | H22: Search share loss, antitrust remedies, slower cloud migration
A23: Gross Margin (%) | B23: 0.56 | C23: 0.555 | D23: 0.55 | E23: 0.545 | F23: 0.54 | G23: 0.54 | H23: Higher TAC and massive data center energy / compute depreciation
A24: S&M Expense (% of Revenue) | B24: 0.08 | C24: 0.08 | D24: 0.078 | E24: 0.078 | F24: 0.078 | G24: 0.078 | H24: Aggressive defensive advertising to protect search volume
A25: R&D Expense (% of Revenue) | B25: 0.145 | C25: 0.145 | D25: 0.14 | E25: 0.14 | F25: 0.14 | G25: 0.14 | H25: Sustained AI talent wars and foundational model retraining
A26: G&A Expense (% of Revenue) | B26: 0.045 | C26: 0.045 | D26: 0.042 | E26: 0.042 | F26: 0.042 | G26: 0.042 | H26: Elevated legal defense costs and regulatory compliance
A27: CapEx (% of Revenue) | B27: 0.39 | C27: 0.3 | D27: 0.22 | E27: 0.18 | F27: 0.14 | G27: 0.1 | H27: Aggressive AI cluster spending with prolonged payback horizon
A28: Terminal Perpetuity Growth (g) / WACC | B28: - | C28: - | D28: - | E28: - | F28: - | G28: 0.025 | H28: Conservative long-term inflation-matching growth (2.50%) | Bear WACC: 12.50%
A29: SCENARIO 2: BASE CASE ASSUMPTIONS (CONSENSUS & STRATEGIC AI BUILD)
A30: Assumption Driver | B30: FY26E | C30: FY27E | D30: FY28E | E30: FY29E | F30: FY30E | G30: Terminal | H30: Parameter Description / Methodology
A31: Revenue Growth Rate (%) | B31: 0.16 | C31: 0.14 | D31: 0.12 | E31: 0.105 | F31: 0.09 | G31: 0.03 | H31: Cloud scaling (+40-50%), YouTube monetization, Gemini Search integration
A32: Gross Margin (%) | B32: 0.58 | C32: 0.582 | D32: 0.585 | E32: 0.588 | F32: 0.59 | G32: 0.59 | H32: Cloud margin expansion and custom TPU silicon cost efficiencies
A33: S&M Expense (% of Revenue) | B33: 0.075 | C33: 0.072 | D33: 0.07 | E33: 0.068 | F33: 0.065 | G33: 0.065 | H33: Operating leverage from digital enterprise distribution
A34: R&D Expense (% of Revenue) | B34: 0.138 | C34: 0.135 | D34: 0.132 | E34: 0.128 | F34: 0.125 | G34: 0.125 | H34: Disciplined R&D scaling with AI-assisted software productivity
A35: G&A Expense (% of Revenue) | B35: 0.042 | C35: 0.04 | D35: 0.038 | E35: 0.036 | F35: 0.035 | G35: 0.035 | H35: Corporate efficiency and automation of back-office operations
A36: CapEx (% of Revenue) | B36: 0.38 | C36: 0.26 | D36: 0.18 | E36: 0.14 | F36: 0.11 | G36: 0.08 | H36: 2026 peak AI CapEx ($178B), normalizing to sustainable steady-state
A37: Terminal Perpetuity Growth (g) / WACC | B37: - | C37: - | D37: - | E37: - | F37: - | G37: 0.03 | H37: GDP+ Tech leader growth (3.00%) | WACC dynamically linked to 'WACC Build'
A38: SCENARIO 3: BULL CASE ASSUMPTIONS (AGENTIC AI & CLOUD ACCELERATION)
A39: Assumption Driver | B39: FY26E | C39: FY27E | D39: FY28E | E39: FY29E | F39: FY30E | G39: Terminal | H39: Parameter Description / Methodology
A40: Revenue Growth Rate (%) | B40: 0.2 | C40: 0.175 | D40: 0.15 | E40: 0.13 | F40: 0.11 | G40: 0.035 | H40: Waymo commercial scaling, Google Workspace AI enterprise ARPU explosion
A41: Gross Margin (%) | B41: 0.59 | C41: 0.595 | D41: 0.6 | E41: 0.605 | F41: 0.61 | G41: 0.61 | H41: High-margin software subscription revenues and TPU 6th gen efficiencies
A42: S&M Expense (% of Revenue) | B42: 0.07 | C42: 0.065 | D42: 0.062 | E42: 0.06 | F42: 0.058 | G42: 0.058 | H42: Self-reinforcing viral adoption of Gemini personal AI assistants
A43: R&D Expense (% of Revenue) | B43: 0.13 | C43: 0.125 | D43: 0.12 | E43: 0.115 | F43: 0.11 | G43: 0.11 | H43: Massive operating leverage across global developer ecosystem
...

Sheet WACC Build
A1: Alphabet Inc. (NASDAQ: GOOGL / GOOG)
A2: Weighted Average Cost of Capital (WACC) Schedule | CAPM Methodology & Capital Structure
A4: I. COST OF EQUITY (CAPM METHODOLOGY)
A5: Risk-Free Rate (10-Yr US Treasury Yield) | B5: 0.0469
A6: Equity Beta (5-Year Monthly vs S&P 500) | B6: 1.24
A7: Market Equity Risk Premium (ERP) | B7: 0.055
A8: Cost of Equity (Ke = Rf + Beta * ERP) | B8: =B5+B6*B7
A10: II. COST OF DEBT & CAPITAL STRUCTURE WEIGHTS
A11: Pre-Tax Cost of Debt (Kd) | B11: 0.0485
A12: Effective Corporate Tax Rate (t) | B12: 0.175
A13: After-Tax Cost of Debt (Kd * (1 - t)) | B13: =B11*(1-B12)
A14: Current Share Price ($) | B14: ='DCF Valuation'!B7
A15: Diluted Shares Outstanding (M) | B15: ='DCF Valuation'!B8
A16: Market Capitalization ($M) | B16: =B14*B15
A17: Total Debt (Current + Noncurrent Debt) ($M) | B17: 98200
A18: Cash, Cash Equivalents & Marketable Securities ($M) | B18: 242500
A19: Net Debt ($M) [Net Cash if negative] | B19: =B17-B18
A20: Enterprise Value ($M) | B20: =B16+B19
A22: III. WACC CALCULATION SUMMARY
A23: Component | B23: Market Value ($M) | C23: Capital Weight (%) | D23: Cost of Capital (%) | E23: Weighted Contribution (%)
A24: Common Equity (Market Cap) | B24: =B16 | C24: =B24/$B$20 | D24: =B8 | E24: =C24*D24
A25: Net Debt (Net Cash Adjustment) | B25: =B19 | C25: =B25/$B$20 | D25: =B13 | E25: =C25*D25
A26: Total Capitalization / Base WACC | B26: =B20 | C26: =SUM(C24:C25) | D26: - | E26: =SUM(E24:E25)
