Workbook

Sheet DCF Valuation
A1: Microsoft Corporation (NASDAQ: MSFT)
A2: Institutional DCF Valuation Model | Report Date: August 19, 2026 | Financial Source: SEC Form 10-K (FY2022-FY2026)
A4: Active Scenario Selector: | B4: 2 | C4: =IF(B4=1,"[1] BEAR CASE (AI Digestion / Cloud Slowdown)",IF(B4=2,"[2] BASE CASE (Consensus AI Cloud Scaling & Copilot Monetization)","[3] BULL CASE (AI Supercycle & Azure Platform Dominance)"))
A6: I. MARKET DATA & CAPITAL STRUCTURE INPUTS
A7: Current Stock Price ($) | B7: 481.59
A8: Diluted Shares Outstanding (M) | B8: 7435
A9: Implied Equity Market Capitalization ($M) | B9: =B7*B8
A10: Cash and Short-Term Investments ($M) | B10: 76843
A11: Total Debt ($M) | B11: 47600
A12: Net Debt ($M) [Net Cash if negative] | B12: =B11-B10
A13: Implied Enterprise Value ($M) | B13: =B9+B12
A14: Effective Corporate Tax Rate (%) | B14: 0.2
A15: Risk-Free Rate (10-Yr US Treasury) (%) | B15: ='WACC Build'!B5
A16: Equity Beta (5-Year Monthly) | B16: ='WACC Build'!B6
A17: Market Equity Risk Premium (ERP) (%) | B17: ='WACC Build'!B7
A18: Base Case WACC (%) | B18: ='WACC Build'!E26
A20: II. SCENARIO ASSUMPTIONS & DRIVER BLOCKS
A21: Driver / Assumption | B21: FY2026A | C21: FY2027E | D21: FY2028E | E21: FY2029E | F21: FY2030E | G21: FY2031E | H21: Terminal / WACC
A22: Bear Case Assumptions (Selector = 1)
A23: Revenue Growth (%) | B23: - | C23: 0.11 | D23: 0.095 | E23: 0.085 | F23: 0.075 | G23: 0.065 | H23: 0.025
A24: Gross Margin (%) | B24: - | C24: 0.675 | D24: 0.675 | E24: 0.67 | F24: 0.665 | G24: 0.66 | H24: -
A25: EBIT Margin (%) | B25: - | C25: 0.455 | D25: 0.45 | E25: 0.445 | F25: 0.44 | G25: 0.435 | H25: 0.115
A26: D&A (% of Revenue) | B26: - | C26: 0.135 | D26: 0.145 | E26: 0.14 | F26: 0.135 | G26: 0.125 | H26: -
A27: CapEx (% of Revenue) | B27: - | C27: 0.3 | D27: 0.26 | E27: 0.22 | F27: 0.18 | G27: 0.15 | H27: -
A28: Δ NWC (% of Δ Revenue) | B28: - | C28: 0.015 | D28: 0.015 | E28: 0.015 | F28: 0.015 | G28: 0.015 | H28: -
A29: Base Case Assumptions (Selector = 2)
A30: Revenue Growth (%) | B30: - | C30: 0.145 | D30: 0.13 | E30: 0.115 | F30: 0.1 | G30: 0.085 | H30: 0.03
A31: Gross Margin (%) | B31: - | C31: 0.685 | D31: 0.69 | E31: 0.695 | F31: 0.7 | G31: 0.702 | H31: -
A32: EBIT Margin (%) | B32: - | C32: 0.47 | D32: 0.478 | E32: 0.486 | F32: 0.493 | G32: 0.5 | H32: ='WACC Build'!E26
A33: D&A (% of Revenue) | B33: - | C33: 0.13 | D33: 0.14 | E33: 0.135 | F33: 0.13 | G33: 0.12 | H33: -
A34: CapEx (% of Revenue) | B34: - | C34: 0.28 | D34: 0.23 | E34: 0.19 | F34: 0.16 | G34: 0.135 | H34: -
A35: Δ NWC (% of Δ Revenue) | B35: - | C35: 0.01 | D35: 0.01 | E35: 0.01 | F35: 0.01 | G35: 0.01 | H35: -
A36: Bull Case Assumptions (Selector = 3)
A37: Revenue Growth (%) | B37: - | C37: 0.175 | D37: 0.16 | E37: 0.14 | F37: 0.125 | G37: 0.105 | H37: 0.035
A38: Gross Margin (%) | B38: - | C38: 0.695 | D38: 0.705 | E38: 0.712 | F38: 0.718 | G38: 0.725 | H38: -
A39: EBIT Margin (%) | B39: - | C39: 0.48 | D39: 0.492 | E39: 0.505 | F39: 0.515 | G39: 0.525 | H39: 0.1
A40: D&A (% of Revenue) | B40: - | C40: 0.125 | D40: 0.135 | E40: 0.13 | F40: 0.125 | G40: 0.115 | H40: -
A41: CapEx (% of Revenue) | B41: - | C41: 0.26 | D41: 0.21 | E41: 0.175 | F41: 0.145 | G41: 0.12 | H41: -
A42: Δ NWC (% of Δ Revenue) | B42: - | C42: 0.01 | D42: 0.01 | E42: 0.01 | F42: 0.01 | G42: 0.01 | H42: -
A43: ACTIVE CONSOLIDATED DRIVERS (PULLED VIA INDEX FORMULAS)
...

Sheet WACC Build
A1: Microsoft Corporation (NASDAQ: MSFT)
A2: Weighted Average Cost of Capital (WACC) Schedule | CAPM Methodology & Capital Structure
A4: I. COST OF EQUITY (CAPM METHODOLOGY)
A5: Risk-Free Rate (10-Yr US Treasury Yield) | B5: 0.0475
A6: Equity Beta (5-Year Monthly vs S&P 500) | B6: 1.1
A7: Market Equity Risk Premium (ERP) | B7: 0.055
A8: Cost of Equity (Ke = Rf + Beta * ERP) | B8: =B5+B6*B7
A10: II. COST OF DEBT & CAPITAL STRUCTURE WEIGHTS
A11: Pre-Tax Cost of Debt (Kd) | B11: 0.0495
A12: Effective Corporate Tax Rate (t) | B12: 0.2
A13: After-Tax Cost of Debt (Kd * (1 - t)) | B13: =B11*(1-B12)
A14: Current Share Price ($) | B14: ='DCF Valuation'!B7
A15: Diluted Shares Outstanding (M) | B15: ='DCF Valuation'!B8
A16: Market Capitalization ($M) | B16: =B14*B15
A17: Total Debt ($M) | B17: 47600
A18: Cash and Short-Term Investments ($M) | B18: 76843
A19: Net Debt ($M) [Net Cash if negative] | B19: =B17-B18
A20: Total Capitalization ($M) | B20: =B16+B17
A22: III. WACC CALCULATION SUMMARY
A23: Component | B23: Market Value ($M) | C23: Capital Weight (%) | D23: Cost of Capital (%) | E23: Weighted Contribution (%)
A24: Common Equity (Market Cap) | B24: =B16 | C24: =B24/$B$20 | D24: =B8 | E24: =C24*D24
A25: Total Debt | B25: =B17 | C25: =B25/$B$20 | D25: =B13 | E25: =C25*D25
A26: Total Capitalization / Base WACC | B26: =B20 | C26: =SUM(C24:C25) | D26: - | E26: =SUM(E24:E25)
