Workbook

Sheet DCF
A1: Maison Solutions Inc. (NASDAQ: MSS) - Institutional DCF Valuation Model
A2: Valuation Date: August 2026 | Currency: USD in Millions (except per-share data) | Fiscal Year Ends April 30
A4: 1. MODEL CONTROL & SCENARIO SELECTOR
A5: Scenario Selector (1 = Bear, 2 = Base, 3 = Bull): | B5: 2
A6: Active Scenario Name: | B6: =IF(B5=1,"Bear Case (Conservative)",IF(B5=2,"Base Case (Consensus / Target)","Bull Case (Optimistic)"))
A8: 2. MARKET DATA & CAPITAL STRUCTURE INPUTS
A9: Current Share Price ($) | B9: 1.46
A10: Diluted Shares Outstanding (M) | B10: 2.53
A11: Current Market Capitalization ($M) | B11: =B9*B10
A12: Cash & Cash Equivalents ($M) | B12: 1.52
A13: Total Debt ($M) | B13: 47.6
A14: Net Debt ($M) | B14: =B13-B12
A15: Effective Corporate Tax Rate (%) | B15: 0.21
A17: 3. SCENARIO ASSUMPTIONS SCHEDULE
A18: Assumption / Parameter | C18: FY2024A | D18: FY2025A | E18: FY2026E | F18: FY2027E | G18: FY2028E | H18: FY2029E | I18: FY2030E | J18: Terminal
A19: BEAR CASE ASSUMPTIONS (1)
A20: Revenue Growth YoY (%) | E20: 0.04 | F20: 0.035 | G20: 0.03 | H20: 0.025 | I20: 0.025 | J20: 0.02
A21: EBIT Margin (%) | E21: 0 | F21: 0.005 | G21: 0.008 | H21: 0.01 | I21: 0.01
A22: Discount Rate / WACC (%) | E22: 0.11
A23: Terminal Growth Rate (%) | E23: 0.02
A24: BASE CASE ASSUMPTIONS (2)
A25: Revenue Growth YoY (%) | E25: 0.08 | F25: 0.07 | G25: 0.06 | H25: 0.05 | I25: 0.04 | J25: 0.025
A26: EBIT Margin (%) | E26: 0.008 | F26: 0.015 | G26: 0.02 | H26: 0.025 | I26: 0.028
A27: Discount Rate / WACC (%) | E27: 0.1
A28: Terminal Growth Rate (%) | E28: 0.025
A29: BULL CASE ASSUMPTIONS (3)
A30: Revenue Growth YoY (%) | E30: 0.14 | F30: 0.12 | G30: 0.1 | H30: 0.08 | I30: 0.06 | J30: 0.03
A31: EBIT Margin (%) | E31: 0.015 | F31: 0.025 | G31: 0.032 | H31: 0.038 | I31: 0.042
A32: Discount Rate / WACC (%) | E32: 0.09
A33: Terminal Growth Rate (%) | E33: 0.03
A35: 4. ACTIVE SCENARIO CONSOLIDATED DRIVERS
A36: Consolidated Driver | C36: FY2024A | D36: FY2025A | E36: FY2026E | F36: FY2027E | G36: FY2028E | H36: FY2029E | I36: FY2030E | J36: Terminal
A37: Selected Revenue Growth (%) | E37: =CHOOSE($B$5,E20,E25,E30) | F37: =CHOOSE($B$5,F20,F25,F30) | G37: =CHOOSE($B$5,G20,G25,G30) | H37: =CHOOSE($B$5,H20,H25,H30) | I37: =CHOOSE($B$5,I20,I25,I30) | J37: =CHOOSE($B$5,J20,J25,J30)
A38: Selected EBIT Margin (%) | E38: =CHOOSE($B$5,E21,E26,E31) | F38: =CHOOSE($B$5,F21,F26,F31) | G38: =CHOOSE($B$5,G21,G26,G31) | H38: =CHOOSE($B$5,H21,H26,H31) | I38: =CHOOSE($B$5,I21,I26,I31)
A39: Selected Discount Rate / WACC (%) | E39: =CHOOSE($B$5,E22,E27,E32)
A40: Selected Terminal Growth Rate (%) | E40: =CHOOSE($B$5,E23,E28,E33)
A41: D&A (% of Revenue) | E41: 0.009 | F41: 0.009 | G41: 0.009 | H41: 0.009 | I41: 0.009
A42: CapEx (% of Revenue) | E42: 0.012 | F42: 0.012 | G42: 0.012 | H42: 0.012 | I42: 0.012
A43: ΔNWC (% of ΔRevenue) | E43: 0.01 | F43: 0.01 | G43: 0.01 | H43: 0.01 | I43: 0.01
A45: 5. FINANCIAL STATEMENT & FREE CASH FLOW PROJECTION SCHEDULE ($M)
...

Sheet WACC
A1: Maison Solutions Inc. (NASDAQ: MSS) - WACC Schedule
A3: CAPITAL ASSET PRICING MODEL (CAPM) & WACC BUILD
A4: Risk-Free Rate (Rf) | B4: 0.047 | C4: US 10-Year Treasury Yield (August 2026)
A5: Equity Beta (β) | B5: 1.2 | C5: Small-cap grocery / specialty retail adjusted beta
A6: Equity Risk Premium (ERP) | B6: 0.055 | C6: Standard institutional market risk premium (5.5%)
A7: Small-Cap Size Premium | B7: 0.02 | C7: Micro-cap liquidity and scale risk premium
A8: Cost of Equity (Ke = Rf + β*ERP + Size) | B8: =B4+B5*B6+B7 | C8: CAPM Cost of Equity
A10: Pre-Tax Cost of Debt (Kd) | B10: 0.09 | C10: Micro-cap borrowing and debt interest rate
A11: Effective Corporate Tax Rate (t) | B11: =DCF!$B$15 | C11: Statutory tax rate
A12: After-Tax Cost of Debt (Kd * (1 - t)) | B12: =B10*(1-B11) | C12: After-tax borrowing cost
A14: Target Equity Weight (We) | B14: 0.5 | C14: Normalized target capital structure
A15: Target Debt Weight (Wd) | B15: 0.5 | C15: Normalized target capital structure
A16: Weighted Average Cost of Capital (WACC) | B16: =B8*B14+B12*B15 | C16: Calculated Base WACC (10.20% normalized)

Sheet Sensitivity
A1: Maison Solutions Inc. (NASDAQ: MSS) - Executive Sensitivity Analysis
A3: TABLE 1: WACC VS. TERMINAL GROWTH RATE (Implied Share Price $)
A4: WACC \ g | B4: 0.015 | C4: 0.02 | D4: 0.025 | E4: 0.03 | F4: 0.035
A5: 0.09 | B5: =DCF!C83 | C5: =DCF!D83 | D5: =DCF!E83 | E5: =DCF!F83 | F5: =DCF!G83
A6: 0.095 | B6: =DCF!C84 | C6: =DCF!D84 | D6: =DCF!E84 | E6: =DCF!F84 | F6: =DCF!G84
A7: 0.1 | B7: =DCF!C85 | C7: =DCF!D85 | D7: =DCF!E85 | E7: =DCF!F85 | F7: =DCF!G85
A8: 0.105 | B8: =DCF!C86 | C8: =DCF!D86 | D8: =DCF!E86 | E8: =DCF!F86 | F8: =DCF!G86
A9: 0.11 | B9: =DCF!C87 | C9: =DCF!D87 | D9: =DCF!E87 | E9: =DCF!F87 | F9: =DCF!G87
