Workbook

Sheet DCF
A1: Space Exploration Technologies Corp. (SpaceX) - Institutional DCF Valuation Model
A2: Ticker: SPCX (NASDAQ) | Date: August 19, 2026 | Historical: 2023A-2025A | Projections: 2026E-2030E | Figures in USD Millions ($M)
A4: SCENARIO CONTROL & ACTIVE CASE SELECTOR
A5: Select Scenario Case (1 = Bear, 2 = Base, 3 = Bull): | B5: 2 | C5: Active Scenario: | D5: =IF(B5=1,"Bear Case",IF(B5=2,"Base Case (Consensus)","Bull Case"))
A7: MARKET DATA & CAPITAL STRUCTURE (USD Millions, except per share)
A8: Current Stock Price ($) | C8: 143.34
A9: Diluted Shares Outstanding (M) | C9: 13570
A10: Implied Market Capitalization ($M) | C10: =C8*C9
A11: Total Debt & Financing Lease Liabilities ($M) | C11: 38430
A12: Cash, Equivalents & Short-Term Investments ($M) | C12: 93520
A13: Net Debt / (Net Cash Position) ($M) | C13: =C11-C12
A14: Enterprise Value (Market EV) ($M) | C14: =C10+C13
A16: SCENARIO 1: BEAR CASE ASSUMPTIONS (CONSERVATIVE ADOPTION)
A17: Key DCF Driver / Assumption | F17: FY2026E | G17: FY2027E | H17: FY2028E | I17: FY2029E | J17: FY2030E | K17: Terminal
A18: Revenue YoY Growth (%) | F18: 1 | G18: 0.8 | H18: 0.5 | I18: 0.45 | J18: 0.35 | K18: -
A19: Gross Profit Margin (%) | F19: 0.36 | G19: 0.38 | H19: 0.4 | I19: 0.42 | J19: 0.44 | K19: -
A20: R&D Expense (% of Revenue) | F20: 0.25 | G20: 0.2 | H20: 0.16 | I20: 0.14 | J20: 0.12 | K20: -
A21: SG&A Expense (% of Revenue) | F21: 0.2 | G21: 0.17 | H21: 0.15 | I21: 0.14 | J21: 0.14 | K21: -
A22: Operating Margin (EBIT %) Target | F22: -0.09 | G22: 0.01 | H22: 0.09 | I22: 0.14 | J22: 0.18 | K22: -
A23: Effective Tax Rate (%) | F23: 0.21 | G23: 0.21 | H23: 0.21 | I23: 0.21 | J23: 0.21 | K23: -
A24: Depreciation & Amortization (% of Rev) | F24: 0.18 | G24: 0.14 | H24: 0.11 | I24: 0.09 | J24: 0.08 | K24: -
A25: Capital Expenditures (% of Rev) | F25: 0.25 | G25: 0.2 | H25: 0.16 | I25: 0.13 | J25: 0.11 | K25: -
A26: Change in NWC (% of Δ Revenue) | F26: 0.015 | G26: 0.015 | H26: 0.015 | I26: 0.015 | J26: 0.015 | K26: -
A27: Terminal Perpetuity Growth Rate (g) | F27: - | G27: - | H27: - | I27: - | J27: - | K27: 0.025
A28: Discount Rate (WACC) | F28: 0.115 | G28: 0.115 | H28: 0.115 | I28: 0.115 | J28: 0.115 | K28: 0.115
A30: SCENARIO 2: BASE CASE ASSUMPTIONS (CONSENSUS & MANAGEMENT ROADMAP)
A31: Key DCF Driver / Assumption | F31: FY2026E | G31: FY2027E | H31: FY2028E | I31: FY2029E | J31: FY2030E | K31: Terminal
A32: Revenue YoY Growth (%) | F32: 1.383 | G32: 1.247 | H32: 0.6 | I32: 0.438 | J32: 0.348 | K32: -
A33: Gross Profit Margin (%) | F33: 0.38 | G33: 0.42 | H33: 0.46 | I33: 0.49 | J33: 0.52 | K33: -
A34: R&D Expense (% of Revenue) | F34: 0.24 | G34: 0.18 | H34: 0.14 | I34: 0.12 | J34: 0.1 | K34: -
A35: SG&A Expense (% of Revenue) | F35: 0.19 | G35: 0.15 | H35: 0.13 | I35: 0.12 | J35: 0.12 | K35: -
A36: Operating Margin (EBIT %) Target | F36: -0.05 | G36: 0.09 | H36: 0.19 | I36: 0.25 | J36: 0.3 | K36: -
A37: Effective Tax Rate (%) | F37: 0.21 | G37: 0.21 | H37: 0.21 | I37: 0.21 | J37: 0.21 | K37: -
A38: Depreciation & Amortization (% of Rev) | F38: 0.18 | G38: 0.14 | H38: 0.11 | I38: 0.09 | J38: 0.08 | K38: -
A39: Capital Expenditures (% of Rev) | F39: 0.25 | G39: 0.18 | H39: 0.14 | I39: 0.11 | J39: 0.09 | K39: -
A40: Change in NWC (% of Δ Revenue) | F40: 0.015 | G40: 0.015 | H40: 0.015 | I40: 0.015 | J40: 0.015 | K40: -
A41: Terminal Perpetuity Growth Rate (g) | F41: - | G41: - | H41: - | I41: - | J41: - | K41: 0.03
A42: Discount Rate (WACC) | F42: =WACC!$B$21 | G42: =WACC!$B$21 | H42: =WACC!$B$21 | I42: =WACC!$B$21 | J42: =WACC!$B$21 | K42: =WACC!$B$21
A44: SCENARIO 3: BULL CASE ASSUMPTIONS (STARSHIP COMMERCIAL SCALE & AI SURGE)
A45: Key DCF Driver / Assumption | F45: FY2026E | G45: FY2027E | H45: FY2028E | I45: FY2029E | J45: FY2030E | K45: Terminal
...

Sheet WACC
A1: Space Exploration Technologies Corp. (SpaceX) - Cost of Capital (WACC)
A2: Ticker: SPCX | Valuation Date: August 19, 2026 | Currency: USD in Millions ($M)
A4: 1. COST OF EQUITY CALCULATION (CAPM METHODOLOGY)
A5: Risk-Free Rate (10-Year US Treasury Yield) | B5: 0.0425
A6: Market Beta (5Y Monthly / Aerospace & Tech Blend) | B6: 1.35
A7: Equity Risk Premium (ERP) | B7: 0.055
A8: Cost of Equity (Ke = Rf + Beta * ERP) | B8: =B5+B6*B7
A10: 2. COST OF DEBT CALCULATION
A11: Pre-Tax Cost of Debt | B11: 0.065
A12: Effective Corporate Tax Rate | B12: =DCF!$F$65
A13: After-Tax Cost of Debt (Kd = Pre-Tax * (1 - Tax Rate)) | B13: =B11*(1-B12)
A15: 3. CAPITAL STRUCTURE & WEIGHTED AVERAGE COST OF CAPITAL (WACC)
A16: Capital Component | B16: Market Value ($M) | C16: Capital Weight (%) | D16: Cost of Capital (%) | E16: Weighted Contribution (%)
A17: Market Capitalization (Equity) | B17: =DCF!$C$10 | C17: =B17/$B$19 | D17: =B8 | E17: =C17*D17
A18: Total Debt & Lease Obligations | B18: =DCF!$C$11 | C18: =B18/$B$19 | D18: =B13 | E18: =C18*D18
A19: Total Capital (Equity + Debt) | B19: =B17+B18 | C19: =SUM(C17:C18) | D19: - | E19: =SUM(E17:E18)
A21: WEIGHTED AVERAGE COST OF CAPITAL (WACC) | B21: =E19
