Workbook

Sheet DCF Valuation
A1: Tesla, Inc. (NASDAQ: TSLA)
A2: Institutional DCF Valuation Model | Report Date: August 19, 2026 | Financial Source: SEC Form 10-K & Consensus Estimates
A4: Active Scenario Selector: | B4: 2 | C4: =IF(B4=1,"[1] BEAR CASE (EV Saturation / Margin Pressure / FSD Delay)",IF(B4=2,"[2] BASE CASE (Next-Gen Platform / Megapack Scale / Steady FSD)","[3] BULL CASE (Autonomous Robotaxi Fleet & Optimus Surge)"))
A6: I. MARKET DATA & CAPITAL STRUCTURE INPUTS
A7: Current Stock Price ($) | B7: 336.5
A8: Diluted Shares Outstanding (M) | B8: 3760
A9: Implied Equity Market Capitalization ($M) | B9: =B7*B8
A10: Cash, Cash Equivalents & ST Investments ($M) | B10: 44059
A11: Total Debt (Current + Noncurrent + Leases) ($M) | B11: 8376
A12: Net Debt ($M) | B12: =B11-B10
A13: Implied Enterprise Value ($M) | B13: =B9+B12
A14: Effective Corporate Tax Rate (%) | B14: 0.21
A15: Risk-Free Rate (10-Yr US Treasury) (%) | B15: ='WACC Build'!B5
A16: Equity Beta (5-Year Monthly) | B16: ='WACC Build'!B6
A17: Market Equity Risk Premium (ERP) (%) | B17: ='WACC Build'!B7
A18: Base Case WACC (%) | B18: ='WACC Build'!E26
A20: II. SCENARIO ASSUMPTIONS & DRIVER BLOCKS
A21: Driver / Assumption | B21: FY2025A | C21: FY2026E | D21: FY2027E | E21: FY2028E | F21: FY2029E | G21: FY2030E | H21: Terminal / WACC
A22: Bear Case Assumptions (Selector = 1)
A23: Revenue Growth (%) | B23: - | C23: 0.05 | D23: 0.06 | E23: 0.07 | F23: 0.06 | G23: 0.05 | H23: 0.025
A24: EBIT Margin (%) | B24: - | C24: 0.05 | D24: 0.06 | E24: 0.07 | F24: 0.075 | G24: 0.08 | H24: 0.155
A25: D&A (% of Revenue) | B25: - | C25: 0.065 | D25: 0.063 | E25: 0.06 | F25: 0.058 | G25: 0.055 | H25: -
A26: CapEx (% of Revenue) | B26: - | C26: 0.09 | D26: 0.088 | E26: 0.085 | F26: 0.082 | G26: 0.08 | H26: -
A27: Δ NWC (% of Δ Revenue) | B27: - | C27: 0.03 | D27: 0.03 | E27: 0.03 | F27: 0.03 | G27: 0.03 | H27: -
A29: Base Case Assumptions (Selector = 2)
A30: Revenue Growth (%) | B30: - | C30: 0.11 | D30: 0.15 | E30: 0.16 | F30: 0.14 | G30: 0.12 | H30: 0.03
A31: EBIT Margin (%) | B31: - | C31: 0.06 | D31: 0.08 | E31: 0.105 | F31: 0.122 | G31: 0.138 | H31: ='WACC Build'!E26
A32: D&A (% of Revenue) | B32: - | C32: 0.058 | D32: 0.055 | E32: 0.052 | F32: 0.05 | G32: 0.048 | H32: -
A33: CapEx (% of Revenue) | B33: - | C33: 0.085 | D33: 0.08 | E33: 0.075 | F33: 0.07 | G33: 0.065 | H33: -
A34: Δ NWC (% of Δ Revenue) | B34: - | C34: 0.025 | D34: 0.025 | E34: 0.025 | F34: 0.025 | G34: 0.025 | H34: -
A36: Bull Case Assumptions (Selector = 3)
A37: Revenue Growth (%) | B37: - | C37: 0.18 | D37: 0.25 | E37: 0.28 | F37: 0.24 | G37: 0.2 | H37: 0.04
A38: EBIT Margin (%) | B38: - | C38: 0.085 | D38: 0.13 | E38: 0.175 | F38: 0.205 | G38: 0.23 | H38: 0.135
A39: D&A (% of Revenue) | B39: - | C39: 0.055 | D39: 0.052 | E39: 0.05 | F39: 0.048 | G39: 0.045 | H39: -
A40: CapEx (% of Revenue) | B40: - | C40: 0.08 | D40: 0.075 | E40: 0.07 | F40: 0.065 | G40: 0.06 | H40: -
A41: Δ NWC (% of Δ Revenue) | B41: - | C41: 0.02 | D41: 0.02 | E41: 0.02 | F41: 0.02 | G41: 0.02 | H41: -
A43: ACTIVE CONSOLIDATED DRIVERS (PULLED VIA INDEX FORMULAS)
A44: Active Revenue Growth (%) | B44: - | C44: =INDEX((C$23,C$30,C$37),1,1,$B$4) | D44: =INDEX((D$23,D$30,D$37),1,1,$B$4) | E44: =INDEX((E$23,E$30,E$37),1,1,$B$4) | F44: =INDEX((F$23,F$30,F$37),1,1,$B$4) | G44: =INDEX((G$23,G$30,G$37),1,1,$B$4) | H44: =INDEX((H$23,H$30,H$37),1,1,$B$4)
A45: Active EBIT Margin (%) | B45: - | C45: =INDEX((C$24,C$31,C$38),1,1,$B$4) | D45: =INDEX((D$24,D$31,D$38),1,1,$B$4) | E45: =INDEX((E$24,E$31,E$38),1,1,$B$4) | F45: =INDEX((F$24,F$31,F$38),1,1,$B$4) | G45: =INDEX((G$24,G$31,G$38),1,1,$B$4) | H45: =INDEX((H$24,H$31,H$38),1,1,$B$4)
A46: Active D&A (% of Revenue) | B46: - | C46: =INDEX((C$25,C$32,C$39),1,1,$B$4) | D46: =INDEX((D$25,D$32,D$39),1,1,$B$4) | E46: =INDEX((E$25,E$32,E$39),1,1,$B$4) | F46: =INDEX((F$25,F$32,F$39),1,1,$B$4) | G46: =INDEX((G$25,G$32,G$39),1,1,$B$4) | H46: -
...

Sheet WACC Build
A1: Tesla, Inc. (NASDAQ: TSLA)
A2: Weighted Average Cost of Capital (WACC) Schedule | CAPM Methodology & Capital Structure
A4: I. COST OF EQUITY (CAPM METHODOLOGY)
A5: Risk-Free Rate (10-Yr US Treasury Yield) | B5: 0.0465
A6: Equity Beta (5-Year Monthly vs S&P 500) | B6: 1.82
A7: Market Equity Risk Premium (ERP) | B7: 0.055
A8: Cost of Equity (Ke = Rf + Beta * ERP) | B8: =B5+B6*B7
A10: II. COST OF DEBT & CAPITAL STRUCTURE WEIGHTS
A11: Pre-Tax Cost of Debt (Kd) | B11: 0.055
A12: Effective Corporate Tax Rate (t) | B12: 0.21
A13: After-Tax Cost of Debt (Kd * (1 - t)) | B13: =B11*(1-B12)
A14: Current Share Price ($) | B14: ='DCF Valuation'!B7
A15: Diluted Shares Outstanding (M) | B15: ='DCF Valuation'!B8
A16: Market Capitalization ($M) | B16: =B14*B15
A17: Total Debt (Current + Noncurrent + Leases) ($M) | B17: 8376
A18: Cash, Cash Equivalents & ST Investments ($M) | B18: 44059
A19: Net Debt ($M) | B19: =B17-B18
A20: Enterprise Value ($M) | B20: =B16+B19
A22: III. WACC CALCULATION SUMMARY
A23: Component | B23: Market Value ($M) | C23: Capital Weight (%) | D23: Cost of Capital (%) | E23: Weighted Contribution (%)
A24: Common Equity (Market Cap) | B24: =B16 | C24: =B24/$B$20 | D24: =B8 | E24: =C24*D24
A25: Net Debt (Debt Weight Adjustment) | B25: =B19 | C25: =B25/$B$20 | D25: =B13 | E25: =C25*D25
A26: Total Capitalization / Base WACC | B26: =B20 | C26: =SUM(C24:C25) | D26: - | E26: =SUM(E24:E25)
