Workbook

Sheet DCF
A1: THE REALREAL, INC. (NASDAQ: REAL) - DISCOUNTED CASH FLOW VALUATION MODEL
A2: Ticker: REAL | Valuation Date: August 19, 2026 | FYE: Dec 31 | Units: USD Millions ($M) except per share
A4: SCENARIO SELECTOR
A5: Case Selector [1 = Bear, 2 = Base, 3 = Bull]: | B5: 2
A6: Active Selected Scenario: | B6: =IF(B5=1,"Bear Case",IF(B5=2,"Base Case","Bull Case"))
A8: MARKET DATA & VALUATION PARAMETERS
A9: Current Stock Price ($) | B9: 11.2
A10: Diluted Shares Outstanding (M) | B10: 121.67
A11: Market Capitalization ($M) | B11: =B9*B10
A12: Total Debt ($M) | B12: =WACC!$B$19
A13: Cash & Cash Equivalents ($M) | B13: =WACC!$B$20
A14: Net Debt ($M) [Total Debt - Cash] | B14: =B12-B13
A15: Baseline WACC (Discount Rate) | B15: =WACC!$B$30
A16: Terminal Growth Rate (g) | B16: 0.025
A18: BEAR CASE ASSUMPTIONS (Scenario 1 - Macro Slowdown & High Friction)
A19: Assumption | B19: FY2026E | C19: FY2027E | D19: FY2028E | E19: FY2029E | F19: FY2030E
A20: Revenue Growth Rate (%) | B20: 0.1 | C20: 0.07 | D20: 0.05 | E20: 0.04 | F20: 0.03
A21: Gross Margin (%) | B21: 0.745 | C21: 0.745 | D21: 0.742 | E21: 0.74 | F21: 0.74
A22: EBIT Margin (%) | B22: 0.025 | C22: 0.03 | D22: 0.038 | E22: 0.045 | F22: 0.05
A23: D&A (% of Revenue) | B23: 0.045 | C23: 0.042 | D23: 0.04 | E23: 0.038 | F23: 0.038
A24: CapEx (% of Revenue) | B24: 0.046 | C24: 0.044 | D24: 0.042 | E24: 0.04 | F24: 0.038
A25: NWC Change (% of Δ Revenue) | B25: 0.025 | C25: 0.025 | D25: 0.025 | E25: 0.025 | F25: 0.025
A27: BASE CASE ASSUMPTIONS (Scenario 2 - Consensus & Management Guidance)
A28: Assumption | B28: FY2026E | C28: FY2027E | D28: FY2028E | E28: FY2029E | F28: FY2030E
A29: Revenue Growth Rate (%) | B29: 0.14374 | C29: 0.12 | D29: 0.1 | E29: 0.08 | F29: 0.06
A30: Gross Margin (%) | B30: 0.755 | C30: 0.76 | D30: 0.765 | E30: 0.77 | F30: 0.775
A31: EBIT Margin (%) | B31: 0.04227 | C31: 0.065 | D31: 0.085 | E31: 0.1 | F31: 0.11
A32: D&A (% of Revenue) | B32: 0.0429 | C32: 0.04 | D32: 0.038 | E32: 0.036 | F32: 0.035
A33: CapEx (% of Revenue) | B33: 0.04416 | C33: 0.042 | D33: 0.04 | E33: 0.038 | F33: 0.035
A34: NWC Change (% of Δ Revenue) | B34: 0.02 | C34: 0.02 | D34: 0.02 | E34: 0.02 | F34: 0.02
A36: BULL CASE ASSUMPTIONS (Scenario 3 - AI Automation & Luxury Penetration Acceleration)
A37: Assumption | B37: FY2026E | C37: FY2027E | D37: FY2028E | E37: FY2029E | F37: FY2030E
A38: Revenue Growth Rate (%) | B38: 0.17 | C38: 0.15 | D38: 0.13 | E38: 0.11 | F38: 0.09
A39: Gross Margin (%) | B39: 0.76 | C39: 0.765 | D39: 0.77 | E39: 0.775 | F39: 0.785
A40: EBIT Margin (%) | B40: 0.05 | C40: 0.08 | D40: 0.105 | E40: 0.12 | F40: 0.135
A41: D&A (% of Revenue) | B41: 0.042 | C41: 0.038 | D41: 0.035 | E41: 0.033 | F41: 0.032
A42: CapEx (% of Revenue) | B42: 0.042 | C42: 0.038 | D42: 0.035 | E42: 0.033 | F42: 0.032
A43: NWC Change (% of Δ Revenue) | B43: 0.015 | C43: 0.015 | D43: 0.015 | E43: 0.015 | F43: 0.015
A45: ACTIVE CONSOLIDATED ASSUMPTIONS (DYNAMICALLY PULLED VIA CHOOSE)
A46: Assumption | B46: FY2026E | C46: FY2027E | D46: FY2028E | E46: FY2029E | F46: FY2030E
...

Sheet WACC
A1: THE REALREAL, INC. (NASDAQ: REAL) - COST OF CAPITAL (WACC)
A2: Valuation Date: August 19, 2026 | Currency: USD ($M) | Investment Banking Standard Model
A4: COST OF EQUITY CALCULATION (CAPM)
A5: Risk-Free Rate (Rf) [10-Year US Treasury] | B5: 0.0469
A6: Beta (β) [Adjusted Forward 5Y Monthly Beta] | B6: 2
A7: Equity Risk Premium (ERP) | B7: 0.055
A8: Cost of Equity (Ke) | B8: =B5+B6*B7
A10: COST OF DEBT CALCULATION
A11: Pre-Tax Cost of Debt (Kd) | B11: 0.075
A12: Marginal Tax Rate (t) | B12: =DCF!$B$53
A13: After-Tax Cost of Debt [Kd * (1 - t)] | B13: =B11*(1-B12)
A15: CAPITAL STRUCTURE & ENTERPRISE VALUE ($M)
A16: Current Stock Price ($) | B16: =DCF!$B$9
A17: Diluted Shares Outstanding (M) | B17: =DCF!$B$10
A18: Market Capitalization (Equity Value) | B18: =B16*B17
A19: Total Debt ($M) | B19: 375.8
A20: Cash & Cash Equivalents ($M) | B20: 119.1
A21: Net Debt ($M) [Total Debt - Cash] | B21: =B19-B20
A22: Enterprise Value ($M) [Market Cap + Net Debt] | B22: =B18+B21
A24: WEIGHTED AVERAGE COST OF CAPITAL (WACC) BREAKDOWN
A25: Capital Component | B25: Amount ($M) | C25: Capital Weight (%) | D25: Cost of Capital (%) | E25: Weighted Cost (%)
A26: Equity | B26: =B18 | C26: =B26/$B$22 | D26: =B8 | E26: =C26*D26
A27: Net Debt | B27: =B21 | C27: =B27/$B$22 | D27: =B13 | E27: =C27*D27
A28: Total Capitalization | B28: =SUM(B26:B27) | C28: =SUM(C26:C27) | D28: - | E28: =SUM(E26:E27)
A30: WEIGHTED AVERAGE COST OF CAPITAL (WACC) | B30: =E28
