Workbook

Sheet DCF
A1: Vital Farms, Inc. (VITL) – DCF Valuation Model
A2: NASDAQ: VITL | Model Date: August 20, 2026 | Fiscal Year End: December
A4: Scenario Selector (1=Bear / 2=Base / 3=Bull):
A5: Selected Case: | B5: 2
B6: =IF(B5=1,"Bear Case",IF(B5=2,"Base Case","Bull Case"))
A8: MARKET DATA & KEY INPUTS
A9: Item | B9: Value
A10: Current Stock Price | B10: 10.87
A11: Diluted Shares Outstanding (M) | B11: 42.9
A12: Market Capitalization ($M) | B12: =B10*B11
A13: Net Debt ($M) [Debt – Cash] | B13: 8.8
A15: BEAR CASE ASSUMPTIONS
A16: Assumption | G16: FY2026E | H16: FY2027E | I16: FY2028E | J16: FY2029E | K16: FY2030E
A17: Revenue Growth (%) | G17: 0.03 | H17: 0.08 | I17: 0.1 | J17: 0.1 | K17: 0.09
A18: Gross Margin (%) | G18: 0.26 | H18: 0.3 | I18: 0.32 | J18: 0.33 | K18: 0.34
A19: EBIT Margin (%) | G19: -0.02 | H19: 0.02 | I19: 0.05 | J19: 0.07 | K19: 0.08
A20: Tax Rate (%) | G20: 0.24
A21: D&A (% of Revenue) | G21: 0.04 | H21: 0.038 | I21: 0.035 | J21: 0.033 | K21: 0.03
A22: CapEx (% of Revenue) | G22: 0.095 | H22: 0.085 | I22: 0.07 | J22: 0.06 | K22: 0.05
A23: NWC Change (% of Δ Revenue) | G23: 0.03 | H23: 0.03 | I23: 0.03 | J23: 0.02 | K23: 0.02
A24: Terminal Growth Rate (%) | G24: 0.025
A25: WACC (%) | G25: 0.115
A27: BASE CASE ASSUMPTIONS
A28: Assumption | G28: FY2026E | H28: FY2027E | I28: FY2028E | J28: FY2029E | K28: FY2030E
A29: Revenue Growth (%) | G29: 0.035 | H29: 0.15 | I29: 0.18 | J29: 0.16 | K29: 0.13
A30: Gross Margin (%) | G30: 0.28 | H30: 0.34 | I30: 0.36 | J30: 0.37 | K30: 0.38
A31: EBIT Margin (%) | G31: 0 | H31: 0.06 | I31: 0.09 | J31: 0.11 | K31: 0.13
A32: Tax Rate (%) | G32: 0.24
A33: D&A (% of Revenue) | G33: 0.038 | H33: 0.035 | I33: 0.032 | J33: 0.03 | K33: 0.028
A34: CapEx (% of Revenue) | G34: 0.092 | H34: 0.075 | I34: 0.06 | J34: 0.05 | K34: 0.045
A35: NWC Change (% of Δ Revenue) | G35: 0.025 | H35: 0.025 | I35: 0.02 | J35: 0.02 | K35: 0.015
A36: Terminal Growth Rate (%) | G36: 0.03
A37: WACC (%) | G37: 0.105
A39: BULL CASE ASSUMPTIONS
A40: Assumption | G40: FY2026E | H40: FY2027E | I40: FY2028E | J40: FY2029E | K40: FY2030E
A41: Revenue Growth (%) | G41: 0.04 | H41: 0.2 | I41: 0.22 | J41: 0.2 | K41: 0.16
A42: Gross Margin (%) | G42: 0.3 | H42: 0.36 | I42: 0.38 | J42: 0.39 | K42: 0.4
A43: EBIT Margin (%) | G43: 0.02 | H43: 0.09 | I43: 0.13 | J43: 0.15 | K43: 0.17
A44: Tax Rate (%) | G44: 0.24
A45: D&A (% of Revenue) | G45: 0.036 | H45: 0.032 | I45: 0.03 | J45: 0.028 | K45: 0.026
...

Sheet WACC
A1: Vital Farms (VITL) — WACC Calculation
A2: Date: August 20, 2026 | CAPM Methodology
A4: COST OF EQUITY — CAPM
A5: Item | B5: Value | C5: Notes
A6: Risk-Free Rate (10Y US Treasury) | B6: 0.0468 | C6: FRED DGS10 — Aug 17 2026
A7: Beta (5-Year) | B7: 1.3756 | C7: GuruFocus, Aug 19 2026
A8: Equity Risk Premium (ERP) | B8: 0.055 | C8: Damodaran, 2026 US ERP
A9: Cost of Equity (CAPM) | B9: =B6+B7*B8 | C9: =Rf + β × ERP
A11: COST OF DEBT
A12: Item | B12: Value
A13: Pre-Tax Cost of Debt | B13: 0.085 | C13: SOFR + spread estimate on new term loan
A14: Tax Rate (for debt shield) | B14: =DCF!$G$55 | C14: Linked from DCF sheet
A15: After-Tax Cost of Debt | B15: =B13*(1-B14)
A17: CAPITAL STRUCTURE
A18: Item | B18: Value
A19: Pre-Tax Cost of Debt (ref) | B19: =B13
A20: Current Stock Price | B20: =DCF!$B$10
A21: Diluted Shares (M) | B21: =DCF!$B$11
A22: Market Capitalization ($M) | B22: =B20*B21
A23: Net Debt ($M) | B23: =DCF!$B$13
A24: Enterprise Value ($M) | B24: =B22+B23
A25: Equity Weight | B25: =IF(B24=0,1,B22/B24)
A26: Debt Weight | B26: =IF(B24=0,0,B23/B24)
A27: WEIGHTED AVG COST OF CAPITAL (WACC) | B27: =D30+D31
A28: WACC CALCULATION
B29: Weight | C29: Cost | D29: Contribution
A30: Equity | B30: =B25 | C30: =B9 | D30: =B30*C30
A31: Debt | B31: =B26 | C31: =B15 | D31: =B31*C31
